<?xml version="1.0"?>
<!--
Humanoid Arm URDF Example

A 5-DOF humanoid arm with:
- Base/Torso (box)
- Shoulder (sphere) - shoulder_pan joint (Y rotation)
- Upper arm (cylinder) - shoulder_lift joint (X rotation)
- Elbow (sphere) - elbow joint (Y rotation)
- Forearm (cylinder) - forearm_roll joint (Z rotation, continuous)
- Hand (box) - wrist joint (Y rotation)

Validate with: check_urdf humanoid_arm.urdf
-->
<robot name="humanoid_arm">

  <!-- Base/Torso -->
  <link name="base_link">
    <visual>
      <geometry>
        <box size="0.3 0.2 0.4"/>
      </geometry>
      <material name="gray">
        <color rgba="0.7 0.7 0.7 1.0"/>
      </material>
    </visual>
    <collision>
      <geometry>
        <box size="0.3 0.2 0.4"/>
      </geometry>
    </collision>
    <inertial>
      <mass value="5.0"/>
      <inertia ixx="0.1" ixy="0" ixz="0"
               iyy="0.1" iyz="0" izz="0.1"/>
    </inertial>
  </link>

  <!-- Shoulder link -->
  <link name="shoulder_link">
    <visual>
      <geometry>
        <sphere radius="0.05"/>
      </geometry>
      <material name="blue">
        <color rgba="0.2 0.2 0.8 1.0"/>
      </material>
    </visual>
    <collision>
      <geometry>
        <sphere radius="0.05"/>
      </geometry>
    </collision>
    <inertial>
      <mass value="0.5"/>
      <inertia ixx="0.001" ixy="0" ixz="0"
               iyy="0.001" iyz="0" izz="0.001"/>
    </inertial>
  </link>

  <!-- Shoulder pan joint (rotation around Y) -->
  <joint name="shoulder_pan" type="revolute">
    <parent link="base_link"/>
    <child link="shoulder_link"/>
    <origin xyz="0.15 0.1 0.15" rpy="0 0 0"/>
    <axis xyz="0 1 0"/>
    <limit lower="-1.57" upper="1.57" effort="100" velocity="1.0"/>
  </joint>

  <!-- Upper arm -->
  <link name="upper_arm_link">
    <visual>
      <origin xyz="0 0 -0.15"/>
      <geometry>
        <cylinder radius="0.03" length="0.3"/>
      </geometry>
      <material name="orange">
        <color rgba="1.0 0.5 0.0 1.0"/>
      </material>
    </visual>
    <collision>
      <origin xyz="0 0 -0.15"/>
      <geometry>
        <cylinder radius="0.03" length="0.3"/>
      </geometry>
    </collision>
    <inertial>
      <origin xyz="0 0 -0.15"/>
      <mass value="1.0"/>
      <inertia ixx="0.01" ixy="0" ixz="0"
               iyy="0.01" iyz="0" izz="0.001"/>
    </inertial>
  </link>

  <!-- Shoulder lift joint (rotation around X) -->
  <joint name="shoulder_lift" type="revolute">
    <parent link="shoulder_link"/>
    <child link="upper_arm_link"/>
    <origin xyz="0 0 0" rpy="0 0 0"/>
    <axis xyz="1 0 0"/>
    <limit lower="-2.0" upper="2.0" effort="100" velocity="1.0"/>
  </joint>

  <!-- Elbow link -->
  <link name="elbow_link">
    <visual>
      <geometry>
        <sphere radius="0.035"/>
      </geometry>
      <material name="blue">
        <color rgba="0.2 0.2 0.8 1.0"/>
      </material>
    </visual>
    <collision>
      <geometry>
        <sphere radius="0.035"/>
      </geometry>
    </collision>
    <inertial>
      <mass value="0.3"/>
      <inertia ixx="0.0005" ixy="0" ixz="0"
               iyy="0.0005" iyz="0" izz="0.0005"/>
    </inertial>
  </link>

  <!-- Elbow joint (rotation around Y) -->
  <joint name="elbow" type="revolute">
    <parent link="upper_arm_link"/>
    <child link="elbow_link"/>
    <origin xyz="0 0 -0.3" rpy="0 0 0"/>
    <axis xyz="0 1 0"/>
    <limit lower="0" upper="2.5" effort="50" velocity="1.0"/>
  </joint>

  <!-- Forearm -->
  <link name="forearm_link">
    <visual>
      <origin xyz="0 0 -0.125"/>
      <geometry>
        <cylinder radius="0.025" length="0.25"/>
      </geometry>
      <material name="green">
        <color rgba="0.0 0.8 0.2 1.0"/>
      </material>
    </visual>
    <collision>
      <origin xyz="0 0 -0.125"/>
      <geometry>
        <cylinder radius="0.025" length="0.25"/>
      </geometry>
    </collision>
    <inertial>
      <origin xyz="0 0 -0.125"/>
      <mass value="0.5"/>
      <inertia ixx="0.003" ixy="0" ixz="0"
               iyy="0.003" iyz="0" izz="0.0005"/>
    </inertial>
  </link>

  <!-- Forearm roll joint (continuous rotation around Z) -->
  <joint name="forearm_roll" type="continuous">
    <parent link="elbow_link"/>
    <child link="forearm_link"/>
    <origin xyz="0 0 0" rpy="0 0 0"/>
    <axis xyz="0 0 1"/>
  </joint>

  <!-- Wrist/Hand -->
  <link name="hand_link">
    <visual>
      <geometry>
        <box size="0.08 0.06 0.02"/>
      </geometry>
      <material name="gray">
        <color rgba="0.6 0.6 0.6 1.0"/>
      </material>
    </visual>
    <collision>
      <geometry>
        <box size="0.08 0.06 0.02"/>
      </geometry>
    </collision>
    <inertial>
      <mass value="0.2"/>
      <inertia ixx="0.0001" ixy="0" ixz="0"
               iyy="0.0001" iyz="0" izz="0.0001"/>
    </inertial>
  </link>

  <!-- Wrist joint (rotation around Y) -->
  <joint name="wrist" type="revolute">
    <parent link="forearm_link"/>
    <child link="hand_link"/>
    <origin xyz="0 0 -0.25" rpy="0 0 0"/>
    <axis xyz="0 1 0"/>
    <limit lower="-1.0" upper="1.0" effort="20" velocity="1.5"/>
  </joint>

</robot>
